<?xml version="1.0" ?>

<robot name="robot">

    <!-- Gazebo Colors -->
    <gazebo reference="base_link">
        <material>Gazebo/Black</material>
    </gazebo>

    <!-- Base Link -->
    <link name="base_link">
        <inertial>
            <mass value="5" />
            <origin xyz="0 0 0" rpy="0 0 0" />
            <inertia ixx="1.5417" ixy="0" ixz="0" iyy="3.467" iyz="0" izz="4.742" />
        </inertial>
        <collision>
            <origin rpy="0 0 0" xyz="0 0 0.15" />
            <geometry>
                <cylinder length="0.30" radius="0.25"/>
            </geometry>
        </collision>
        <visual>
            <origin rpy="0 0 0" xyz="0 0 0" />
            <geometry>
                <cylinder length="0.30" radius="0.25"/>
            </geometry>
        </visual>
    </link>

    <!-- Base Footprint -->
    <link name="base_footprint">
        <inertial>
            <mass value="0" />
            <origin xyz="0 0 0" rpy="0 0 0" />
            <inertia ixx="0" ixy="0" ixz="0" iyy="0" iyz="0" izz="0" />
        </inertial>
    </link>
    <joint name="joint_base_footprint" type="fixed">
        <origin rpy="0 0 0" xyz="0 0 -0.15" />  
        <child link="base_footprint" />
        <parent link="base_link" />
    </joint>

    <!-- Joint / left wheel -->
    <joint name="joint_left_wheel" type="continuous">
        <origin rpy="0 0 0" xyz="0 0.2 -0.15" />
        <child link="link_left_wheel" />
        <parent link="base_link" />
        <axis rpy="0 0 0" xyz="0 1 0" />
        <limit effort="10000" velocity="1000" />
        <joint_properties damping="1.0" friction="1.0" />
    </joint>
    <!-- Link - left wheel -->
    <link name="link_left_wheel">
        <inertial>
            <mass value="1.5" />
            <origin xyz="0 0 0" rpy="0 0 0" />
            <inertia ixx="0.002526666666667" ixy="0" ixz="0" iyy="0.002526666666667" iyz="0" izz="0.005"/>
        </inertial>
        <collision>
            <origin rpy="1.5707 0 0" xyz="0 0 0" />
            <geometry>
                <cylinder length="0.05" radius="0.025"/>
            </geometry>
        </collision>
        <visual>
            <origin rpy="1.5707 0 0" xyz="0 0 0" />
            <geometry>
                <cylinder length="0.05" radius="0.025"/>
            </geometry>
            <material name="Red">
                <color rgba="0.8 0.1 0.1 1" />
            </material>
        </visual>
    </link>

    <!-- Joint / right wheel -->
    <joint name="joint_right_wheel" type="continuous">
        <origin rpy="0 0 0" xyz="0 -0.2 -0.15" />
        <child link="link_right_wheel" />
        <parent link="base_link" />
        <axis rpy="0 0 0" xyz="0 1 0" />
        <limit effort="10000" velocity="1000" />
        <joint_properties damping="1.0" friction="1.0" />
    </joint>
    <!-- Link - right wheel -->
    <link name="link_right_wheel">
        <inertial>
            <mass value="1.5" />
            <origin xyz="0 0 0" rpy="0 0 0" />
            <inertia ixx="0.002526666666667" ixy="0" ixz="0" iyy="0.002526666666667" iyz="0" izz="0.005"/>
        </inertial>
        <collision>
            <origin rpy="1.5707 0 0" xyz="0 0 0" />
            <geometry>
                <cylinder length="0.05" radius="0.025"/>
            </geometry>
        </collision>
        <visual>
            <origin rpy="1.5707 0 0" xyz="0 0 0" />
            <geometry>
                <cylinder length="0.05" radius="0.025"/>
            </geometry>
            <material name="Red">
                <color rgba="0.8 0.1 0.1 1" />
            </material>
        </visual>
    </link>

    <!-- Joint - front caster wheel -->
    <joint name="joint_front_caster_wheel" type="fixed">
        <origin rpy="0 0 0" xyz="0.1 0 -0.15" />
        <child link="link_front_caster_wheel" />
        <parent link="base_link" />
        <joint_properties damping="1.0" friction="0.0" />
    </joint>
    <!-- Link - front caster wheel -->
    <link name="link_front_caster_wheel">
        <inertial>
            <mass value="1.5" />
            <origin xyz="0 0 0" rpy="0 0 0" />
            <inertia ixx="0.002526666666667" ixy="0" ixz="0" iyy="0.002526666666667" iyz="0" izz="0.005"/>
        </inertial>
        <!-- Caster wheel support -->
        <collision>
            <origin rpy="0 0 0" xyz="0 0 0.045" />
            <geometry>
                <sphere radius="0.035" />
            </geometry>
        </collision>
        <visual>
            <origin rpy="0 0 0" xyz="0 0 0.045" />
            <geometry>
                <sphere radius="0.035" />
            </geometry>
            <material name="DarkBlue">
                <color rgba="0.2 0.2 0.4 0.1" />
            </material>
        </visual>
        <!-- Caster wheel -->
        <collision>
            <origin rpy="0 0 0" xyz="0 0 0" />
            <geometry>
                <sphere radius="0.025" />
            </geometry>
        </collision>
        <visual>
            <origin rpy="0 0 0" xyz="0 0 0" />
            <geometry>
                <sphere radius="0.025" />
            </geometry>
            <material name="Grey">
                <color rgba="0.6 0.6 0.6 1" />
            </material>
        </visual>
    </link>

    <!-- Joint - back caster wheel -->
    <joint name="joint_back_caster_wheel" type="fixed">
        <origin rpy="0 0 0" xyz="-0.1 0 -0.15" />
        <child link="link_back_caster_wheel" />
        <parent link="base_link" />
        <joint_properties damping="1.0" friction="0.0" />
    </joint>
    <!-- Link - back caster wheel -->
    <link name="link_back_caster_wheel">
        <inertial>
            <mass value="1.5" />
            <origin xyz="0 0 0" rpy="0 0 0" />
            <inertia ixx="0.002526666666667" ixy="0" ixz="0" iyy="0.002526666666667" iyz="0" izz="0.005"/>
        </inertial>
        <!-- Caster wheel support -->
        <collision>
            <origin rpy="0 0 0" xyz="0 0 0.045" />
            <geometry>
                <sphere radius="0.035" />
            </geometry>
        </collision>
        <visual>
            <origin rpy="0 0 0" xyz="0 0 0.045" />
            <geometry>
                <sphere radius="0.035" />
            </geometry>
            <material name="DarkBlue">
                <color rgba="0.2 0.2 0.4 0.1" />
            </material>
        </visual>
        <!-- Caster wheel -->
        <collision>
            <origin rpy="0 0 0" xyz="0 0 0" />
            <geometry>
                <sphere radius="0.025" />
            </geometry>
        </collision>
        <visual>
            <origin rpy="0 0 0" xyz="0 0 0" />
            <geometry>
                <sphere radius="0.025" />
            </geometry>
            <material name="Grey">
                <color rgba="0.6 0.6 0.6 1" />
            </material>
        </visual>
    </link>

    <!-- Laser scan -->
    <joint name="joint_laser_scan" type="fixed">
        <origin rpy="3.141592 0 0" xyz="0.25 0 0.075" />
        <child link="front_laser" />
        <parent link="base_link" />
        <joint_properties damping="1.0" friction="1.0" />
    </joint>
    <link name="front_laser">
        <inertial>
            <origin xyz="0 0 0" rpy="0 0 0" />
            <mass value="0.0" />
            <inertia ixx="0" ixy="0" ixz="0" iyy="0" iyz="0" izz="0"/>
        </inertial>
    </link>


    <gazebo>
        <plugin name="differential_drive_controller" filename="libgazebo_ros_diff_drive.so">
            <updateRate>50</updateRate>
            <leftJoint>joint_left_wheel</leftJoint>
            <rightJoint>joint_right_wheel</rightJoint>
            <wheelSeparation>0.4</wheelSeparation>
            <wheelDiameter>0.05</wheelDiameter>
            <wheelAcceleration>2.0</wheelAcceleration>
            <wheelTorque>20</wheelTorque>
            <commandTopic>/cmd_vel</commandTopic>
            <odometryTopic>odom</odometryTopic>
            <odometryFrame>odom</odometryFrame>
            <robotBaseFrame>base_footprint</robotBaseFrame>
            <odometrySource>1</odometrySource>
            <publishWheelTF>true</publishWheelTF>
            <publishOdom>true</publishOdom>
            <publishWheelJointState>true</publishWheelJointState>
            <legacyMode>false</legacyMode>
        </plugin>
    </gazebo>

    <gazebo reference="front_laser">
        <sensor type="ray" name="head_hokuyo_sensor">
        <pose>0 0 0 0 0 0</pose>
        <visualize>false</visualize>
        <update_rate>40</update_rate>
        <ray>
            <scan>
            <horizontal>
                <samples>720</samples>
                <resolution>1</resolution>
                <min_angle>-1.570796</min_angle>
                <max_angle>1.570796</max_angle>
            </horizontal>
            </scan>
            <range>
            <min>0.10</min>
            <max>30.0</max>
            <resolution>0.01</resolution>
            </range>
            <noise>
            <type>gaussian</type>
            <!-- Noise parameters based on published spec for Hokuyo laser
                achieving "+-30mm" accuracy at range < 10m.  A mean of 0.0m and
                stddev of 0.01m will put 99.7% of samples within 0.03m of the true
                reading. -->
            <mean>0.0</mean>
            <stddev>0.01</stddev>
            </noise>
        </ray>
        <plugin name="gazebo_ros_head_hokuyo_controller" filename="libgazebo_ros_laser.so">
            <topicName>/scan</topicName>
            <frameName>front_laser</frameName>
        </plugin>
        </sensor>
    </gazebo>

</robot>