<?xml version="1.0" ?>

<robot name="robot">
    <!-- Base Link -->
    <link name="base_link">
        <inertial>
            <mass value="19" />
            <origin xyz="0 0 0" rpy="0 0 0" />
            <inertia ixx="0.4394" ixy="0" ixz="0" iyy="0.4394" iyz="0" izz="0.5938" />
        </inertial>
        <collision>
            <origin rpy="0 0 0" xyz="0 0 0.15" />
            <geometry>
                <cylinder length="0.30" radius="0.25"/>
            </geometry>
        </collision>
        <visual>
            <origin rpy="0 0 0" xyz="0 0 0" />
            <geometry>
                <cylinder length="0.30" radius="0.25"/>
            </geometry>
            <material name="Blue">
                <color rgba="0.1 0.1 0.9 0.6" />
            </material>
        </visual>
    </link>

    <!-- Base Footprint -->
    <link name="base_footprint">
        <inertial>
            <mass value="0" />
            <origin xyz="0 0 0" rpy="0 0 0" />
            <inertia ixx="0" ixy="0" ixz="0" iyy="0" iyz="0" izz="0" />
        </inertial>
    </link>
    <joint name="joint_base_footprint" type="fixed">
        <origin rpy="0 0 0" xyz="0 0 -0.15" />  
        <child link="base_footprint" />
        <parent link="base_link" />
    </joint>

    <!-- Joint / left wheel -->
    <joint name="joint_left_wheel" type="continuous">
        <origin rpy="0 0 0" xyz="0 0.2 -0.15" />
        <child link="link_left_wheel" />
        <parent link="base_link" />
        <axis rpy="0 0 0" xyz="0 1 0" />
        <limit effort="10000" velocity="1000" />
        <joint_properties damping="1.0" friction="1.0" />
    </joint>
    <!-- Link - left wheel -->
    <link name="link_left_wheel">
        <inertial>
            <mass value="1.5" />
            <origin xyz="0 0 0" rpy="0 0 0" />
            <inertia ixx="0.000008" ixy="0" ixz="0" iyy="0.000008" iyz="0" izz="0.000012"/>
        </inertial>
        <collision>
            <origin rpy="1.5707 0 0" xyz="0 0 0" />
            <geometry>
                <cylinder length="0.05" radius="0.025"/>
            </geometry>
        </collision>
        <visual>
            <origin rpy="1.5707 0 0" xyz="0 0 0" />
            <geometry>
                <cylinder length="0.05" radius="0.025"/>
            </geometry>
            <material name="Red">
                <color rgba="0.8 0.1 0.1 1" />
            </material>
        </visual>
    </link>

    <!-- Joint / right wheel -->
    <joint name="joint_right_wheel" type="continuous">
        <origin rpy="0 0 0" xyz="0 -0.2 -0.15" />
        <child link="link_right_wheel" />
        <parent link="base_link" />
        <axis rpy="0 0 0" xyz="0 1 0" />
        <limit effort="10000" velocity="1000" />
        <joint_properties damping="1.0" friction="1.0" />
    </joint>
    <!-- Link - right wheel -->
    <link name="link_right_wheel">
        <inertial>
            <mass value="1.5" />
            <origin xyz="0 0 0" rpy="0 0 0" />
            <inertia ixx="0.000008" ixy="0" ixz="0" iyy="0.000008" iyz="0" izz="0.000012"/>
        </inertial>
        <collision>
            <origin rpy="1.5707 0 0" xyz="0 0 0" />
            <geometry>
                <cylinder length="0.05" radius="0.025"/>
            </geometry>
        </collision>
        <visual>
            <origin rpy="1.5707 0 0" xyz="0 0 0" />
            <geometry>
                <cylinder length="0.05" radius="0.025"/>
            </geometry>
            <material name="Red">
                <color rgba="0.8 0.1 0.1 1" />
            </material>
        </visual>
    </link>

    <!-- Joint - front caster wheel -->
    <joint name="joint_front_caster_wheel" type="fixed">
        <origin rpy="0 0 0" xyz="0.1 0 -0.15" />
        <child link="link_front_caster_wheel" />
        <parent link="base_link" />
        <joint_properties damping="1.0" friction="0.0" />
    </joint>
    <!-- Link - front caster wheel -->
    <link name="link_front_caster_wheel">
        <inertial>
            <mass value="1.5" />
            <origin xyz="0 0 0" rpy="0 0 0" />
            <inertia ixx="0.01875" ixy="0" ixz="0" iyy="0.01875" iyz="0" izz="0.01875" />
            <inertia offset="0 0 0.1" ixx="0.005625" ixy="0" ixz="0" iyy="0.005625" iyz="0" izz="0.005625" />
        </inertial>
        <!-- Caster wheel support -->
        <collision>
            <origin rpy="0 0 0" xyz="0 0 0.035" />
            <geometry>
                <sphere radius="0.035" />
            </geometry>
        </collision>
        <visual>
            <origin rpy="0 0 0" xyz="0 0 0.035" />
            <geometry>
                <sphere radius="0.035" />
            </geometry>
            <material name="DarkBlue">
                <color rgba="0.2 0.2 0.4 0.1" />
            </material>
        </visual>
        <!-- Caster wheel -->
        <collision>
            <origin rpy="0 0 0" xyz="0 0 0" />
            <geometry>
                <sphere radius="0.025" />
            </geometry>
        </collision>
        <visual>
            <origin rpy="0 0 0" xyz="0 0 0" />
            <geometry>
                <sphere radius="0.025" />
            </geometry>
            <material name="Grey">
                <color rgba="0.6 0.6 0.6 1" />
            </material>
        </visual>
    </link>

    <!-- Joint - back caster wheel -->
    <joint name="joint_back_caster_wheel" type="fixed">
        <origin rpy="0 0 0" xyz="-0.1 0 -0.15" />
        <child link="link_back_caster_wheel" />
        <parent link="base_link" />
        <joint_properties damping="1.0" friction="0.0" />
    </joint>
    <!-- Link - back caster wheel -->
    <link name="link_back_caster_wheel">
        <inertial>
            <mass value="1.5" />
            <origin xyz="0 0 0" rpy="0 0 0" />
            <inertia ixx="0.01875" ixy="0" ixz="0" iyy="0.01875" iyz="0" izz="0.01875" />
            <inertia offset="0 0 -0.1" ixx="0.005625" ixy="0" ixz="0" iyy="0.005625" iyz="0" izz="0.005625" />
        </inertial>
        <!-- Caster wheel support -->
        <collision>
            <origin rpy="0 0 0" xyz="0 0 0.035" />
            <geometry>
                <sphere radius="0.035" />
            </geometry>
        </collision>
        <visual>
            <origin rpy="0 0 0" xyz="0 0 0.035" />
            <geometry>
                <sphere radius="0.035" />
            </geometry>
            <material name="DarkBlue">
                <color rgba="0.2 0.2 0.4 0.1" />
            </material>
        </visual>
        <!-- Caster wheel -->
        <collision>
            <origin rpy="0 0 0" xyz="0 0 0" />
            <geometry>
                <sphere radius="0.025" />
            </geometry>
        </collision>
        <visual>
            <origin rpy="0 0 0" xyz="0 0 0" />
            <geometry>
                <sphere radius="0.025" />
            </geometry>
            <material name="Grey">
                <color rgba="0.6 0.6 0.6 1" />
            </material>
        </visual>
    </link>

    <!-- Laser scan -->
    <joint name="joint_laser_scan" type="fixed">
        <origin rpy="3.141592 0 0" xyz="0.25 0 0.075" />
        <child link="front_laser" />
        <parent link="base_link" />
        <joint_properties damping="1.0" friction="1.0" />
    </joint>
    <link name="front_laser">
        <inertial>
            <origin xyz="0 0 0" rpy="0 0 0" />
            <mass value="0.0" />
            <inertia ixx="0" ixy="0" ixz="0" iyy="0" iyz="0" izz="0"/>
        </inertial>
    </link>


</robot>